Workbook

Sheet 読み方
A1: TOKIUM 直アポ大 — G列・H列の検証結果
A3: 全4,422行を検証しました。判断基準は御社からご提供いただいた RULES.md が唯一の根拠です。
A5: シートの使い方
A6: ① 検証結果 … 全4,422行。I列（検証結果）とJ列（出典）をこのままシートに貼れます。
A7: 元のシートのI2セルに、H列とI列の2列ぶんを貼ってください。行は欠番なく1行目=行2です。
A8: ② 集計 … 判定の内訳。COUNTIFで①を参照しているので、①を直せば数字が追随します。
A9: ③ G列訂正 … G列の記載に誤りがあった行。売上高の数値・決算期・単体連結の別のいずれかが違います。
A10: ④ 要確認（薄いマージン）… 架電可だが300億円の基準に近く、数値が少し違うと判定が反転する行。
A11: ⑤ 先方確認事項 … §7-1（catr.jp）はこちらで「認める」と確定させました。経緯と、
A12: 残る論点（営業収益の扱い等）を記載しています。
A13: ⑥ 再検証で見直した行 … 検索枠が回復したあとに掛け直して判定が変わった行。
A14: 「架電不可へ」＝誤って載っていたので取り下げた行。「架電可へ」＝回収できた行。
... A28: 本文を開ける環境であれば、これらの多くは回収または確定ができます。

Sheet 検証結果
A1: 行 | B1: 取引先ID | C1: 法人番号 | D1: 取引先名 | E1: 元H判定 | F1: 最終判定 | G1: 架電可 | H1: I列_検証結果 | I1: J列_ソース
A2: 2 | B2: 001Nn00000eVELJ | C2: 1050001001165 | D2: 常洋水産株式会社 | E2: ○ | F2: 架電可 | G2: ○ | H2: ○ 妥当（1次の△を覆す）：どちらの数値を採っても300億を大きく超え、架電可否の結論は動かない。追加でjoyosuisan.com「会社概要」「ごあいさつ」を3クエリ再検索したが、いずれも1次と同じ「2025年3月期 売上高388.39億円／経常利益6.08億円／従業員 男220名・女136名（2025年3月31日現在）」を返した。従業員数の基準日が2025年3月31日で固定されている＝検索インデックスが1期前のスナップショットであることを示しており、G列の398.64億円（2026年3月期）と矛盾しない（388.39億→398.64億で前期比+2.6%）。加えてRULES §6-1は当該ページの表記が「398. 64億円」と小数点が分断されている実例として記録し、§8は常洋水産398.64億をローカルスクレイパーとエージェントの独立2手法で一致確認済みと記録している。法人格は株式会社、独立系（親会社）、出典は自社HP会社概要＝承認ソース①、鮮度も§3-8を満たす。1次の「要再確認」のままでは架電できたはずの企業を落とす側の実害（RULES §1）が出るため○に倒す。残る論点はG列の期表記のみで、判定・金額規模には影響しない。 | I2: https://www.joyosuisan.com/%E4%BC%9A%E7%A4%BE%E6%A6%82%E8%A6%81; https://www.joyosuisan.com/%E3%81%94%E3%81%82%E3%81%84%E3%81%95%E3%81%A4
A3: 3 | B3: 001Nn00000eVELT | C3: 9300001008400 | D3: 伊藤ハム米久フーズ株式会社 | E3: ○ | F3: 架電可 | G3: ○ | H3: ○ 妥当：伊藤ハム米久HDの子会社だが単体で1,200億円級＝300億超のため子会社ルール（§3-3）を満たす。法人格は株式会社、出典はグループ公式サイト（承認ソース）。なお同ドメイン内の採用ページ（会社／伊藤ハム米久フーズ）では「売上高1,219億円」表記、外部集計では2025年3月期1,231.76億円とされており、G列の1,228億円とは期ずれによる差異の可能性がある。300億基準に対して桁が大きく離れているため判定への影響はなし。 | I3: https://www.itoham-yonekyu-holdings.com/foods/; https://www.itoham-yonekyu-holdings.com/Portals/0/saiyo/group/foods/
A4: 4 | B4: 001Nn00000eVELU | C4: 2010401046060 | D4: フォンテラジャパン株式会社 | E4: ○ | F4: 架電可（回収） | G4: ○ | H4: ○ 回収（§7-1確定）：フォンテラジャパン株式会社 単体859.71億円（第45期・2025年7月期）。金額は独立の検索結果でも第45期売上高約859.7億円と一致し整合。§6-6で警告されている流通値「800億2,500万円」（Yahoo!しごとカタログ／SalesNow／Baseconnect）には引きずられていない。法人格は株式会社で問題なく（§3-6充足）、外資日本法人だが単体で300億を大きく超える（§3-3充足）。決算期も直近3期以内で§3-8充足。出典は官報決算公告（catr.jp 収録）。§7-1 は承認する方針で確定。 | I4: https://catr.jp/companies/620b2/148115/settlements/cc9b1/435657; https://ryo-nakamura1.hatenablog.jp/entry/2026/01/30/170000_4
A5: 5 | B5: 001Nn00000eVEba | C5: 6180001081173 | D5: ヤマザキマザックトレーディング株式会社 | E5: △ | F5: 架電不可（元△判定が妥当と確認） | G5: × | H5: ○ 妥当：H列の記載内容を裏取りできた。catr.jpの同社ページに収録されているのは第56期（1,002.81億円）・第57期（1,316.48億円）・第58期（1,445.88億円）までで、それ以降の売上高開示は検索でも発見できず。H列の「2020年3月期時点では1,445.88億円（第58期）」は金額・期ともに整合し、§3-8（直近3期以内でなければ確認不可）に従ってG列「確認不可」・H列△とした処理はルール通り。当たったソースの列挙もある。なお参考値の出典がcatr.jpである点は§7-1の未確定事項だが、結論が除外側のため架電事故のリスクはない。 | I5: https://catr.jp/companies/6a0df/27605; https://catr.jp/settlements/d7da0/189352; https://www.mazak.com/jp-ja/about-us/company-outline/
A6: 6 | B6: 001Nn00000eVM5f | C6: 7010001034873 | D6: カーギルジャパン合同会社 | E6: × | F6: 架電不可（元×判定が妥当と確認） | G6: × | H6: ○ 妥当：社名どおり合同会社であり§3-6により法人格NG。売上高を調べる必要がなく、G列「対象外（合同会社）」・H列「× 法人格」の書式もルール§4通り。RULES §8の検出済み事例（6行目 カーギルジャパン合同会社）とも一致。
A7: 7 | B7: 001Nn00000eVM5o | C7: 2010401082262 | D7: 東和産業株式会社 | E7: △ | F7: 架電不可（元△判定が妥当と確認） | G7: × | H7: ○ 妥当：法人番号2010401082262はgBizINFO上「東和産業株式会社（東京都港区新橋3-20-1）」で、towa-js.co.jp（UNO／DUO／ZoRoN／アサヒを運営するアミューズメント企業、1974年設立、代表 岸野誠）と一致。§6-2の同名法人取り違えはなし（冷凍空調の東和産業株式会社・家庭日用品のTOWA東和産業とは別法人）。売上高は「2025年4月期982億円／2024年4月期923億円」がマイナビ転職・doda・Baseconnect・NIKKEI COMPASS等の禁止ソースにのみ掲載され、自社HP企業情報には売上高記載なし。§6-6そのものの型であり、G列「確認不可」・H列△は正しい。軽微な点として、H列のURLは/business/company-information/だが検索でヒットする企業情報ページは/business/company.htmlであり、リンク切れの可能性があるため差し替えが望ましい。 | I7: https://info.gbiz.go.jp/hojin/ichiran?hojinBango=2010401082262; http://www.towa-js.co.jp/business/company.html
A8: 8 | B8: 001Nn00000eVM5z | C8: 1180001093025 | D8: 加藤化学株式会社 | E8: △ | F8: 架電不可（元△判定が妥当と確認） | G8: × | H8: ○ 妥当：自社HPの企業情報ページおよび採用サイト「ABOUT（数字で見る加藤化学）」を検索で当たったが、いずれにも売上高の記載を確認できなかった。RULES §6-6が「加藤化学 → 確認不可が正解」と名指しで記載している事例そのもので、流通している『2024年3月期 761億8,200万円』（就活会議・Baseconnect・doda等）を採用していない点も正しい。G列「確認不可」・H列△＋当たったソースの列挙という書式も§4に適合。 | I8: https://www.katokagaku.co.jp/corporate/company.html; https://www.katokagaku.co.jp/saiyo/about/
A9: 9 | B9: 001Nn00000eVM6E | C9: 6180001036004 | D9: ゴムノイナキ株式会社 | E9: ○ | F9: 架電可 | G9: ○ | H9: ○ 妥当：自社HP会社概要（inaki.co.jp/company/profile.html）で「売上高428億円（2026年4月期／海外子会社を除く＝単体）」を確認でき、G列の428.20億円（42,820百万円）と桁・単位ともに一致。決算期4月30日という記載も整合。法人格は株式会社、承認ソース①（自社公式サイト会社概要）で300億超が裏取りできており○判定は正しい。 | I9: https://inaki.co.jp/company/profile.html
A10: 10 | B10: 001Nn00000eVM6U | C10: 2180001094419 | D10: 豊田スチールセンター株式会社 | E10: × | F10: 架電不可（元×判定が妥当と確認） | G10: × | H10: ○ 妥当：第66期（決算末日2026年3月31日）売上高189億6,500万円を独立に確認でき、G列の189.65億円と完全一致。前期第65期は200.36億円で推移も整合。法人番号2180001094419はgBizINFO上「豊通メタルソリューションズ株式会社」となっており、H列の商号変更の注記も正しい。豊田通商の子会社で単体300億未満＝§3-3により一律NG、G列の【300億未満】プレフィックスも§4通り付与されている。旧基準686.64億円の併記も§6-3の要求どおり。 | I10: https://info.gbiz.go.jp/hojin/ichiran?hojinBango=2180001094419; https://catr.jp/companies/f5f17/26831; https://prtimes.jp/finance/2180001094419/settlement
A11: 11 | B11: 001Nn00000eVM6a | C11: 6010701007411 | D11: 株式会社ＪＡＬＵＸ | E11: ○ | F11: 架電可 | G11: ○ | H11: ○ 妥当：親子関係の記載は正しく、JALUXはSJフューチャーHD48.14%／双日22.22%／日本航空21.56%／日本空港ビルデング8.08%の出資構成で日本航空の連結子会社。子会社だが単体426.92億円で300億超のため§3-3を満たし、出典もjalux.com（自社サイトの決算公告PDF）＝承認ソース。§6-4の確定値（単体426.92億円／連結892.26億円）とも一致。ただし軽微な整合性の問題として、H列は単体を第65期（2026年3月期）としながら参考の連結値を2025年3月期と記載しており期がずれている。また検索上はjalux.comの決算公告ページで確認できる最新が第64期と表示され、引用PDF（jalux_closing_2606.pdf）の存在をWebSearchでは確認できなかった。金額・判定への影響はないが期の表記は整理が望ましい。 | I11: https://www.jalux.com/profile/fin_announcements.html; https://www.jalux.com/profile/information.html
A12: 12 | B12: 001Nn00000eVM6f | C12: 4100001025387 | D12: 綿半ソリューションズ株式会社 | E12: ○ | F12: 架電可 | G12: ○ | H12: ○ 妥当：出典が綿半HDの有価証券報告書「関係会社の状況」＝承認ソース②で、子会社単体値を親の連結値と取り違えていない（§6-4クリア）。綿半HDの2026年3月期連結売上高が1,354.51億円であること、および綿半ソリューションズが「売上高（内部売上高を除く）の連結売上高に占める割合が10%超」の関係会社として有報に記載されていることを確認でき、単体376.34億円という規模感と矛盾しない。単体300億超のため子会社ルールも満たす。なお有報PDF本文はWebSearchの全文検索対象外のため376.34億円という数値そのものの再読み取りはできていない（同社の官報決算公告は貸借対照表のみで売上高非掲載）。 | I12: https://catr.jp/settlements/60eef/208272; https://catr.jp/companies/65fc6/20903; https://finance.yahoo.co.jp/quote/3199.T/financials
A13: 13 | B13: 001Nn00000eVM6p | C13: 4500001004796 | D13: ヤマキ株式会社 | E13: ○ | F13: 架電可 | G13: ○ | H13: ○ 妥当：自社HP「ヤマキの想いと会社概要」に「売上高 524億円（2025年度）」「社員数682名（2026年4月現在）」と明記されているのを確認でき、G列・H列の記載およびURLが完全に一致。法人格は株式会社、承認ソース①（自社公式サイト会社概要）、鮮度も直近期で§3-8を満たす。 | I13: https://www.yamaki.co.jp/corporate/greeting.html
A14: 14 | B14: 001Nn00000eVU37 | C14: 1240001030013 | D14: エフピコ商事株式会社 | E14: ○ | F14: 架電可 | G14: ○ | H14: ○ 妥当：自社ドメイン内の採用ページ「数字で見るエフピコ商事」（承認ソース系統⑨）に「売上高 309億円（2025年3月期）」と記載されているのを確認でき、G列と一致。同ページの従業員数が「2026年1月時点189名」と最新のため、2025年3月期が現時点の最新公表値と判断でき§3-8も満たす。エフピコの子会社だが単体309億円で300億以上のため§3-3をクリアしており、親の連結値2,221億円を流用していない点も正しい。ただし基準300億に対し9億円しか余裕がないため、次期公表値が出たら再チェック推奨。 | I14: https://www.fp-trading.jp/recruit/number/; https://www.fp-trading.jp/company/outline/
A15: 15 | B15: 001Nn00000eVVX8 | C15: 8140001059873 | D15: 大和工業株式会社 | E15: ○ | F15: 架電可 | G15: ○ | H15: ○ 妥当：2026年3月期決算短信（2026年4月30日開示）の連結売上高1,603億8,900万円＝160,389百万円＝1,603.89億円を独立に確認でき、G列・H列の金額、決算期、連結の別、開示日すべて一致。桁の検算も一致（160,389百万円÷100＝1,603.89億円）。上場親会社のため連結値の採用は§3-3に適合。H列のxj-storage URLの文書番号140120260428513638も、検索でヒットした開示PDF（20260428513638.pdf）と同一文書。 | I15: https://finance-frontend-pc-dist.west.edge.storage-yahoo.jp/disclosure/20260430/20260428513638.pdf; https://www.yamatokogyo.co.jp/ir/library/summary.php; https://www.nikkei.com/article/DGXZQOUF305O80Q5A430C2000000/
A16: 16 | B16: 001Nn00000eVVXG | C16: 3470001000263 | D16: アオイ電子株式会社 | E16: ○ | F16: 架電可 | G16: ○ | H16: ○ 妥当：2026年3月期決算短信（2026年5月8日）の連結売上高38,323百万円＝383.23億円を確認でき、G列・H列の金額・決算期・連結の別・開示日、さらにH列のURLまで検索結果と完全一致。桁の検算も一致（38,323百万円÷100＝383.23億円）。内訳（集積回路33,874百万円＋機能部品4,445百万円＝38,319百万円、ほぼ一致）とも整合。上場企業・株式会社・承認ソース②（決算短信）で問題なし。 | I16: https://www.aoi-electronics.co.jp/ir_category/library/summary/; https://www.aoi-electronics.co.jp/wp-content/uploads/2026/05/20260508-1.pdf
A17: 17 | B17: 001Nn00000eVVXR | C17: 3140001012993 | D17: 株式会社合食 | E17: ○ | F17: 架電可 | G17: ○ | H17: ○ 妥当。みなと新聞(みなと山口合同新聞社=新聞社ソース、§3-4④)で「2026年3月期・単体・売上高360億9200万円(前期比6.7%減)」を確認、G列360.92億円と一致。決算期・単体の別も一致。株式会社・独立系親会社で単体300億超のため○で正しい。※H列記載の記事URL(163557)自体は検索結果に現れなかったが、同紙の合食決算記事連番(23年3月期134332/24年3月期144088/25年3月期153769)と内容が整合。 | I17: https://www.minato-yamaguchi.co.jp/minato/e-minato/articles/tag/s/合食; https://www.minato-yamaguchi.co.jp/minato/e-minato/articles/153769
A18: 18 | B18: 001Nn00000eVVXT | C18: 4120901008588 | D18: 株式会社モリタ | E18: ○ | F18: 架電可 | G18: ○ | H18: ○ 妥当。自社HP会社概要(承認ソース①)に「売上高 1,081億8,366万円(2026年3月末現在)」の記載を確認、G列1,081.84億円と一致(1,081億8,366万円→1,081.84億円、検算OK)。§6-2の同名企業リスクはgBizINFOで法人番号4120901008588＝大阪府吹田市垂水町3-33-18・歯科医療機器卸・従業員1,011名と照合でき、消防車のモリタ(モリタHD系)ではないことを確認。 | I18: https://japan.morita.com/company/profile/index.html; https://info.gbiz.go.jp/hojin/ichiran?hojinBango=4120901008588
... A20: 20 | B20: 001Nn00000eVVXY | C20: 5080401003894 | D20: 日星電気株式会社 | E20: ○ | F20: 架電可 | G20: ○ | H20: ○ 妥当(注記あり)。出典の自社採用ページ「データで見る日星電気」(自社ドメイン内、§5-3⑨の承認ソース)は実在を確認。売上高は独立検索で「460億円(2025年11月)」「440億円(2024年11月)」と同社ページ由来の値が返り、G列約460億円と整合。非上場・独立系(住友電工等の子会社である事実は確認できず)のため§3-3では親会社扱いとなり単体でもグループでも300億超で○。※ただし同社は11月期決算とみられ、G列「2025年度」は「2025年11月期」と明記した方が正確。 | I20: https://www.nissei-el.co.jp/recruit/data/; https://www.nissei-el.co.jp/company/outline/
A21: 21 | B21: 001Nn00000eVVXZ | C21: 6010401016712 | D21: アボットジャパン合同会社 | E21: × | F21: 架電不可（元×判定が妥当と確認） | G21: × | H21: ○ 妥当。社名のとおり合同会社であり§3-6により法人格NG。G列「対象外（合同会社）」・H列「× 法人格。直アポ大は株式会社のみ。合同会社のため対象外」はいずれも§4の記入例どおりで、売上高を調べる必要もない(§3-1①)。RULES§8の既検出例(21行目 アボットジャパン合同会社)とも一致。
A22: 22 | B22: 001Nn00000eVVXc | C22: 7290001012769 | D22: 株式会社翔薬 | E22: ○ | F22: 架電可（回収） | G22: ○ | H22: ○ 回収（§7-1確定）：株式会社翔薬 単体1,970.68億円（2026年3月期）。金額は独立検索でも売上高1,970億6,800万円（前年比6.56%増）と一致し整合。スズケンの完全子会社だが単体で300億を大きく超えるため§3-3充足。自社HP会社概要・スズケンIRには売上高の記載がなく、承認ソースは官報決算公告のみ。決算期は直近期で§3-8充足。出典は官報決算公告（catr.jp 収録）。§7-1 は承認する方針で確定。 | I22: https://catr.jp/companies/546e2/14488; https://www.shoyaku.com/company/companyinfo/index.html
A23: 23 | B23: 001Nn00000eVVXe | C23: 1010001034994 | D23: 日本パーカライジング株式会社 | E23: ○ | F23: 架電可 | G23: ○ | H23: ○ 妥当。2026年3月期第3四半期(累計)連結売上高1,010億16百万円(前年同期比4.7%増)を自社IR開示で確認でき、通期138,155百万円=1,381.55億円と整合(桁の検算OK)。上場親会社のため連結値採用は§3-3に適合し、単体45,776百万円=457.76億円でも300億超。※通期確報の数値そのものはWebSearchのsnippetでは再現できず、四半期開示との整合による確認。 | I23: https://www.parker.co.jp/ja/ir/room/accounting.html; https://www.parker.co.jp/ja/_pdf/topics/03acda2947b22aeaa58a6c2fbe453848c01fc90a.pdf
A24: 24 | B24: 001Nn00000eVVXf | C24: 7500001014710 | D24: ユニ・チャームプロダクツ株式会社 | E24: ○ | F24: 架電可 | G24: ○ | H24: ○ 妥当。出典の自社HP決算公告ページ(unicharmproducts.co.jp/kessan/、承認ソース①/§5-3⑤)の実在を確認。256,886,573千円=2,568億8,657万円→2,568.87億円で桁の検算OK。ユニ・チャーム100%子会社だが単体で300億を大きく超えるため§3-3の子会社基準を満たし判定○は正しい。RULES§5-3の既検証実績(ユニ・チャームプロダクツ2,568.87億円)とも一致。※PDF本文の数値はsnippetでは再現できず。 | I24: https://www.unicharmproducts.co.jp/kessan/
A25: 25 | B25: 001Nn00000eVVXi | C25: 5190001014736 | D25: 株式会社グリーンズ | E25: ○ | F25: 架電可 | G25: ○ | H25: ○ 妥当。2026年6月期決算短信(2026年8月13日適時開示)で連結売上高53,998百万円(前期比8.8%増)を確認、53,998百万円=539.98億円で桁の検算OK、決算期・連結の別ともG列と一致。上場親会社のため連結値採用も§3-3に適合。 | I25: https://www.nikkei.com/nkd/disclosure/tdnr/20260811517439/; https://finance.yahoo.co.jp/quote/6547.T/financials
A26: 26 | B26: 001Nn00000eVVXj | C26: 6010701026130 | D26: 東罐興業株式会社 | E26: ○ | F26: 架電可 | G26: ○ | H26: ○ 妥当。自社HP会社概要ページ(承認ソース①)の実在を確認。金額はRULES§8で独立2手法により670億で一致確認済みの行であり、加えて決算公告ベースの第114期売上高約644.8億円という前期水準とも整合する(670億は+約4%)。東洋製罐グループHDの子会社だが単体670億円で300億超のため§3-3の子会社基準を満たし判定○は正しい。※会社概要ページ本文の数値はsnippetでは再現できず。 | I26: https://www.tokan.co.jp/company/outline/; https://www.tokan.co.jp/company/
A27: 27 | B27: 001Nn00000eVVXk | C27: 3120101026862 | D27: 株式会社近商ストア | E27: ○ | F27: 架電可 | G27: ○ | H27: ○ 妥当。出典の自社HP会社概要・沿革ページ(承認ソース①)の実在を確認し、独立検索でも「近商ストアの売上高は2025年3月実績で581億円」と返りG列(2024年度＝2025年3月期・581億円)と一致。近鉄リテールHDの子会社だが単体581億円で300億超のため§3-3の子会社基準を満たす。決算期も直近3期以内で§3-8に適合。※会社概要ページ本文の数値はsnippetでは再現できず。 | I27: https://www.kinshostore.co.jp/company/overview/; https://www.kintetsu-g-hd.co.jp/group-info/distribution.html
A28: 28 | B28: 001Nn00000eVVXr | C28: 1010001092605 | D28: ヤマト運輸株式会社 | E28: ○ | F28: 架電可 | G28: ○ | H28: ○ 妥当。1,677,534百万円=1兆6,775億3,400万円→16,775.34億円で桁の検算OK。出典の自社HP電子公告(決算公告)は同ディレクトリの第20期公告(kessan_koukoku_202403.pdf)の実在が確認でき、H列URL(kessan_koukoku_202603.pdf=第22期・2026年3月期)は命名規則と期ずれが整合。ヤマトHDの子会社だが単体で300億を大幅超のため§3-3を満たし、運送業のため営業収益を採用した旨もH列に明記済み(§3-7に適合)。 | I28: https://www.kuronekoyamato.co.jp/ytc/corp/corporate/pdf/kessan_koukoku_202403.pdf; https://www.yamato-hd.co.jp/investors/financials/result.html
A29: 29 | B29: 001Nn00000eVVaw | C29: 1010401021766 | D29: 株式会社ニッショク | E29: ○ | F29: 架電不可（保留） | G29: × | H29: 保留 検証不可：G列505.52億円(2025年3月期)を承認ソースで確認できず。当たった経路=①自社HP企業情報 http://www.nisshoku.com/about/ (ページ実在・東京都港区浜松町・1976年創業・病院/介護/学校向け食材供給までは確認できたが売上高の記載を確認できず) ②gBizINFO(法人番号1010401021766で法人の存在と社名は照合できたが財務情報なし) ③官報決算公告・EDINET・新聞記事(該当なし) ④一般検索では「500億円を超える売上」の記述がIndeed等の求人媒体=禁止ソース(§3-4/§6-6)にしか見当たらず。加えて同社は富士産業(株)の食材仕入れ部門として創業した経緯があり、富士産業グループの子会社であれば§3-3の子会社判定(単体300億以上のみ可)と単体/連結の別の明示が必要。親子関係の裏取りも併せて再確認されたい。 | I29: http://www.nisshoku.com/about/; https://info.gbiz.go.jp/hojin/ichiran?hojinBango=1010401021766
A30: 30 | B30: 001Nn00000eVVcg | C30: 8010401054826 | D30: 日本甜菜製糖株式会社 | E30: ○ | F30: 架電可 | G30: ○ | H30: ○ 妥当。2026年3月期・連結売上高686.96億円(前期比6.0%増)を確認、68,696百万円=686.96億円で桁の検算OK、決算期・連結の別ともG列と一致。上場親会社のため連結値採用も§3-3に適合。H列のPDFも自社IRドメイン(nitten.co.jp)配下で承認ソース。 | I30: https://www.nitten.co.jp/ir/library/financial/; https://www.nitten.co.jp/dcms_media/other/2026-2Q_Supplementary_explanation.pdf
A31: 31 | B31: 001Nn00000eVVci | C31: 2290001041302 | D31: 株式会社リョーユーパン | E31: ○ | F31: 架電可 | G31: ○ | H31: ○ 妥当。出典の自社HP会社案内ページ(承認ソース①)の実在を確認し、独立検索でも「連結年商474億円、単体412億円(2026年3月期)、グループ従業員1,198名、本社=福岡県大野城市」と返りG列474億円(2026年3月期・グループ連結)と一致。同社はリョーユーパングループの親会社のため連結値採用は§3-3に適合し、仮に単体412億円で判定しても300億超のため結論は変わらない。 | I31: https://www.ryoyupan.co.jp/about/; https://www.ryoyupan.co.jp/about/group/
A32: 32 | B32: 001Nn00000eVVjy | C32: 4010001102162 | D32: 株式会社デジタルホールディングス | E32: × | F32: 架電不可（元×判定が妥当と確認） | G32: × | H32: ○ 妥当。H列記載の決算短信URL（2025年12月期・2026年2月9日開示）が自社IRサイト上に実在することを検索で確認。博報堂DYHDのTOBによる2026年3月19日上場廃止も同短信の記載どおり。131.02億円はRULES.md §6-3の記載値と一致し、旧基準616.46億円の併記も§6-3の要求を満たす。×（300億未満）判定は正しい。 | I32: https://www.digital-holdings.co.jp/files/topics/5586.pdf; https://www.digital-holdings.co.jp/ir/latest_documents/
A33: 33 | B33: 001Nn00000eVVlk | C33: 2010401092245 | D33: 日本マイクロソフト株式会社 | E33: ○ | F33: 架電可 | G33: ○ | H33: ○ 妥当（ただし2点注記）。H列記載の日経クロステック記事URLは実在し、内容も「官報決算公告（2023年11月13日）に基づき2023年6月期＝2022年7月〜2023年6月の売上高は前年比15.4%増の1兆223億円」でG列と一致。桁も1兆223億円＝10,223億円で誤読なし。注記(1)決算期が2023年6月期＝3期前で§3-8「直近3期以内」の下限。同誌には2024年売上高ランキング記事があり、より新しい期の数値が存在する可能性が高いので更新推奨。注記(2)日経クロステックは日経BP（出版社）であり§3-4の「新聞社」に該当するかはグレー（禁止ソースではない）。金額規模（1兆円）から300億基準の充足自体に疑義はなく○判定は妥当。 | I33: https://xtech.nikkei.com/atcl/nxt/column/18/00848/00119/; https://xtech.nikkei.com/atcl/nxt/column/18/00848/00153/
... A440: 440 | B440: 001Nn00000eVZtA | C440: 3010701005946 | D440: 大成温調株式会社 | E440: ○ | F440: 架電可 | G440: ○ | H440: ○ 妥当：東証上場の親会社（1904）。2026年3月期決算短信（2026/5/13）で連結売上高617.19億円（前期比▲1.3%）、営業利益39.8億円、経常利益45.97億円を確認。H列引用PDF（taisei-oncho.co.jp/ir/files/2026/05.13.26_1.pdf）の実在も確認。 | I440: https://www.taisei-oncho.co.jp/ir/files/2026/05.13.26_1.pdf
A441: 441 | B441: 001Nn00000eVZtC | C441: 3010405007306 | D441: 全国酪農業協同組合連合会 | E441: × | F441: 架電不可（元×判定が妥当と確認） | G441: × | H441: ○ 妥当：既存の「× 法人格」判定が正しい（架電対象外のまま）。法人番号3010405007306の登記商号が『全国酪農業協同組合連合会』＝農業協同組合連合会（全酪連）。§3-6のNG法人格に農業協同組合が明記されており、売上高の如何にかかわらず一律対象外。E列1,000億円以上は判定に無関係。法人格は登記商号で確定するため追加検索不要（0クエリ）。
A442: 442 | B442: 001Nn00000eVZtD | C442: 7010601014110 | D442: 株式会社ヒューテックノオリン | E442: △ | F442: 架電不可（△要再確認） | G442: × | H442: △ 要再確認：直接の親会社は(株)C&Fロジホールディングス（2015年統合、2024年10月9日上場廃止、最終親会社SGホールディングス）。同社有報「関係会社の状況」でヒューテックノオリンが連結営業収益10%超の主要な損益情報等の開示対象と確認できたが、反証層でcflogi.co.jpドメイン限定検索まで行っても金額を抽出できず。自社IRは2015年3月期（上場廃止時）までで経路消尽。決算公告はcatr第70期・prtimes第73期があり1953年設立から第73期＝2026年3月期の可能性はあるが、流通値が446.17億／499億／521.98億と揺れ確定不可。 | I442: https://www.cflogi.co.jp/ir-list/securities/; https://www.cflogi.co.jp/uploads/info230629-2.pdf; https://prtimes.com/finance/7010601014110/settlement; https://catr.jp/companies/02e19/11162; https://www.hutechnorin.co.jp/invest/notice/
A443: 443 | B443: 001Nn00000eVZtF | C443: 5020001022615 | D443: 相模鉄道株式会社 | E443: △ | F443: 架電不可（△要再確認） | G443: × | H443: △ 要再確認（期番号が対象法人と不整合）：反証層で沿革を確認。現・相模鉄道株式会社（法番5020001022615）は2009年9月16日に「相鉄準備会社」が商号変更し新設分割で鉄道事業を承継した新法人で第1期は2010年3月期。よって2026年3月期は第17期前後のはずで、catrの第58〜60期（274.20億／298.28億／355.18億）は当該法人と整合せず決算期を特定できない（§3-8・§6-2）。§7-1も未決着。相鉄HD有報で相模鉄道が特定子会社とは確認できたが金額は抽出不可。同有報の直読が唯一の回収経路。 | I443: https://www.sotetsu.co.jp/about/companies/sagami-railway/; https://www.sotetsu.co.jp/about/companies/sotetsu-holdings/; https://catr.jp/companies/1a024/20794; https://www.sotetsu.co.jp/ir/financial/security/
A444: 444 | B444: 001Nn00000eVZtL | C444: 8120001059652 | D444: 積水ハウス株式会社 | E444: ○ | F444: 架電可 | G444: ○ | H444: ○ 妥当：東証プライム・名証上場の親会社（1928）。2026年1月期決算短信（2026/3/5）で連結売上高4兆1,979億円（前期比+3.4%）、営業利益3,414億円、純利益2,320億円を確認。H列引用PDFのURLも検索結果と完全一致。桁検算OK（4,197,922百万円=41,979.22億円）。 | I444: https://www.sekisuihouse.co.jp/company/financial/library/ir_document/_227230/2025_kessan/t20260305.pdf
A445: 445 | B445: 001Nn00000eVZtM | C445: 6011401007577 | D445: 株式会社ハウステック | E445: ○ | F445: 架電可 | G445: ○ | H445: ○ 妥当（注記：子会社）：自社HP会社概要に2025年度売上高648億円（連結）の記載を確認。ただし同社はヤマダホールディングスの連結子会社。採用値はハウステック自身の連結であり、親会社ヤマダHDのグループ連結（1.6兆円規模）を当てたものではないため§3-3の典型的誤りには当たらない。関連会社は日化メンテナンス・中部日化サービス等の小規模保守会社のみ。厳密な単体値は未取得だが、300億は大きく上回る。社名変更なし。 | I445: https://www.housetec.co.jp/company/overview/
A446: 446 | B446: 001Nn00000eVZtO | C446: 8430001001789 | D446: 岩田地崎建設株式会社 | E446: ○ | F446: 架電可 | G446: ○ | H446: ○ 妥当：自社HP「業績の推移」ページで売上高合計105,051百万円＝1,050.51億円を確認（令和7年度＝2026年3月期。G列「2025年度」と同一年度を指す）。桁検算OK（105,051百万円→1,050.51億円）。同ページの前年度1,044.25億円とも整合。北海道の総合建設会社で親会社なし（旧ドメインiwata-gr.co.jpも同社）。※令和7年度の数値そのものは検索要約では再現できず、規模のみ裏取り。 | I446: https://www.iwatachizaki.jp/kigyo/zaimu/gyoseki.html;https://www.iwatachizaki.jp/kigyo/gaiyou.html
A447: 447 | B447: 001Nn00000eVZtP | C447: 5120001083408 | D447: 大末建設株式会社 | E447: ○ | F447: 架電可 | G447: ○ | H447: ○ 妥当：東証上場（証券コード1814）。2026年3月期の連結営業利益65億7,900万円・連結営業利益率6.2%の開示から売上高は約1,055億円で、G列1,055億円と整合。連結受注高1,543億5,700万円・繰越工事高1,799億3,900万円。自社IR決算短信で確認可。親会社なし。 | I447: https://www.daisue.co.jp/ir/library/financial_reports/;https://finance.logmi.jp/articles/384516
...

Sheet 集計
A1: 区分 | B1: 行数 | C1: 割合 | D1: 意味
A2: 架電可 | B2: =COUNTIF(検証結果!$F$2:$F$4423,A2) | C2: =IFERROR(B2/$B$11,0) | D2: G/H列の記載が正しく、そのまま架電してよい
A3: 架電可（G列訂正あり） | B3: =COUNTIF(検証結果!$F$2:$F$4423,A3) | C3: =IFERROR(B3/$B$11,0) | D3: 架電してよいが、G列に訂正が必要
A4: 架電可（回収） | B4: =COUNTIF(検証結果!$F$2:$F$4423,A4) | C4: =IFERROR(B4/$B$11,0) | D4: 元は除外されていたが、承認ソースを見つけて戻した
A5: 架電不可（△要再確認） | B5: =COUNTIF(検証結果!$F$2:$F$4423,A5) | C5: =IFERROR(B5/$B$11,0) | D5: 承認ソースで売上高を確認できない。§3-5により載せられない
A6: 架電不可（元×判定が妥当と確認） | B6: =COUNTIF(検証結果!$F$2:$F$4423,A6) | C6: =IFERROR(B6/$B$11,0) | D6: 元から除外されており、その除外が正しいと確認した
A7: 架電不可（×要修正） | B7: =COUNTIF(検証結果!$F$2:$F$4423,A7) | C7: =IFERROR(B7/$B$11,0) | D7: 300億円未満・法人格NG等が確定した
A8: 架電不可（元△判定が妥当と確認） | B8: =COUNTIF(検証結果!$F$2:$F$4423,A8) | C8: =IFERROR(B8/$B$11,0) | D8: 元の確認不可判定が正しいと確認した
A9: 架電不可（保留） | B9: =COUNTIF(検証結果!$F$2:$F$4423,A9) | C9: =IFERROR(B9/$B$11,0) | D9: 上記のいずれにも当てはまらない
A10: 架電可 合計 | B10: =COUNTIF(検証結果!$G$2:$G$4423,"○") | C10: =IFERROR(B10/$B$11,0)
A11: 全行 | B11: =COUNTA(検証結果!$A$2:$A$4423) | C11: =IFERROR(B11/$B$11,0)
A12: 架電不可 合計 | B12: =B11-B10 | C12: =IFERROR(B12/$B$11,0)

Sheet G列訂正
A1: 行 | B1: 取引先ID | C1: 法人番号 | D1: 取引先名 | E1: 最終判定 | F1: G列の訂正指示 | G1: I列_検証結果
A2: 98 | B2: 001Nn00000eVW3i | C2: 1140001010033 | D2: 株式会社ニチリン | E2: 架電可（G列訂正あり） | F2: G列訂正：正確には736.68億円）：2025年12月期の連結売上高736億6,800万円を確認 | G2: ○ 妥当（G列訂正：正確には736.68億円）：2025年12月期の連結売上高736億6,800万円を確認。G列「736億円」は端数を落とした表記のため、736.68億円（2025年12月期・連結）と記載するのが正確。判定は変わらない。なお自社HP会社概要記載の単体349億円も300億を超えるため、仮に子会社判定になっても§3-3を満たす。
A3: 145 | B3: 001Nn00000eVWO1 | C3: 3010401035013 | D3: 株式会社日本ケアサプライ | E3: 架電可（G列訂正あり） | F3: G列訂正：単体表記に是正）：2026年3月期の連結売上高349億2,988万円（前期比+9.1%）を決算短信（TDnet ID 20260511523714／2026年5月12日開示）で独立再確認 | G3: ○ 妥当（G列訂正：単体表記に是正）：2026年3月期の連結売上高349億2,988万円（前期比+9.1%）を決算短信（TDnet ID 20260511523714／2026年5月12日開示）で独立再確認。ただし当社は三菱商事の連結子会社であり、§3-3では子会社は単体で判定するためG列は「345.32億円（2026年3月期・単体）」と記すべき（連結値の採用は§6-4に抵触）。単体・連結いずれも300億超のため判定は○のまま。※単体345.32億円は1次が有報から引用した値で、本反証では独立再現に至らず。
A4: 168 | B4: 001Nn00000eVWbF | C4: 1011801030720 | D4: 株式会社サンベルクス | E4: 架電可（G列訂正あり） | F4: G列訂正：「単体」表記は誤りの可能性大）：反証検証で、1,402億円（2026年2月期）を金額シードで検索すると株式会社サンベルクスではなく「株式会社サンベルクスホールディングス」の数値として返り（正社員1,4 | G4: ○ 妥当（G列訂正：「単体」表記は誤りの可能性大）：反証検証で、1,402億円（2026年2月期）を金額シードで検索すると株式会社サンベルクスではなく「株式会社サンベルクスホールディングス」の数値として返り（正社員1,480名／パート4,552名・2025年12月現在）、sunbelx.comにドメイン限定して同じ金額をシードすると当該値は返らず採用サイトの「サンベルクスホールディングスグループ全体で売上高1,200億円突破を目前」のみが返った。よって1,402億円はHDグループ全体の値であり、株式会社サンベルクス(1011801030720)は同HD傘下の事業会社＝§3-3の子会社と見るのが妥当で、単体値は承認ソース上に明示がない。ただしスーパーベルクス53店舗・従業員約6,000名を運営する中核事業会社であり単体が300億を下回る余地はないため架電可否は○を維持。G列は「1,402億円（2026年2月期・サンベルクスHDグループ）」と訂正し、単体値は未確認と注記されたい。
A5: 190 | B5: 001Nn00000eVXBY | C5: 1140001060846 | D5: ハリマ共和物産株式会社 | E5: 架電可（G列訂正あり） | F5: G列訂正：598.43億円が正）：2026年3月期（連結、コード7444）の連結売上高は59,843百万円＝598.43億円（前期比3.2%減、純利益15億1,300万円） | G5: ○ 妥当（G列訂正：598.43億円が正）：2026年3月期（連結、コード7444）の連結売上高は59,843百万円＝598.43億円（前期比3.2%減、純利益15億1,300万円）。G列は598.44億円で端数1百万円ぶんの差があるため厳密には598.43億円に訂正。300億以上・連結・上場親会社という判定自体は変わらず架電可否は○のまま。決算期は直近期で鮮度問題なし。
A6: 191 | B6: 001Nn00000eVXBZ | C6: 1120001087841 | D6: ピップ株式会社 | E6: 架電可（G列訂正あり） | F6: G列訂正：決算期・単体連結の別が未記載）：反証検証で2,215億円をシード検索したところ、ピップ株式会社の決算公告（第79期）として売上高2,210億9,200万円が返り、G列の2,215億円と一致しなかった（ | G6: ○ 妥当（G列訂正：決算期・単体連結の別が未記載）：反証検証で2,215億円をシード検索したところ、ピップ株式会社の決算公告（第79期）として売上高2,210億9,200万円が返り、G列の2,215億円と一致しなかった（第79期＝単体。営業利益6.14億／経常利益20.79億／純利益14.29億）。§6-1の桁・数値照合上、G列の「2,215億円」は221,509百万円と221,092百万円の読み違い、または単体と別系統（グループ2,676億円）の混在が疑われる。またpipjapan.co.jpにドメイン限定しても会社概要ページ上に売上高の記載を再現できず、出所は決算公告（catr.jp＝§7-1の未承認ソース）に依存している。ただし単体・グループのいずれの系統でも2,200億円超で300億を大幅に超え、同社はフジモトHD等を傘下に持つグループ親会社のため§3-3上どちらでも適合し架電可否は○。G列は「約2,211億円（第79期・単体／決算公告）」と決算期を特定のうえ訂正されたい。
A7: 196 | B7: 001Nn00000eVXBy | C7: 1430001010672 | D7: 株式会社ツルハ | E7: 架電不可（元△判定が妥当と確認） | F7: G列訂正 | G7: ○ 妥当（G列訂正）：判定○は維持。ただし1次の「ツルハHD有報 関係会社の状況 126,019百万円(2025年5月期)」は金額シード検索で一度も再現せず、citation を確認できない。代わりにツルハHD自社HP IR「2024年5月期決算説明会資料」の事業会社別売上高が承認ソース経路として存在し、(株)ツルハ＝150,826百万円(＝1,508.26億円)との返りと87,112百万円との返りが混在し値は未確定。いずれにせよ1,433店舗を擁するグループ中核事業会社で単体871〜1,508億円と300億を大きく超え、子会社単体基準§3-3を満たすため判定は安定。G列の金額・決算期は原本PDF照合で確定させること。
A8: 201 | B8: 001Nn00000eVXNm | C8: 1020001052483 | D8: オートコムジャパン株式会社 | E8: 架電可（G列訂正あり） | F8: G列訂正：975億円（2025年9月期）がより新しい）：自社ドメインの採用ページ「数字で見るオートコムジャパン」(corporate.autocj.co.jp/recruit/date/)に売上高推移が掲載され | G8: ○ 妥当（G列訂正：975億円（2025年9月期）がより新しい）：自社ドメインの採用ページ「数字で見るオートコムジャパン」(corporate.autocj.co.jp/recruit/date/)に売上高推移が掲載され、2021年9月期354億円→2022年9月期754億円→2023年9月期754億円→2024年9月期897億円→2025年9月期975億円。G列の897億円（2024年9月期）は1期古いため975億円（2025年9月期）へ更新されたい。いずれにせよ300億を大きく超え架電可否は○のまま。同社は非上場だが自社ドメインの採用ページは§5-3の承認ソース9系統に該当。適格請求書番号T1020001052483による法人番号一致という既存注記も妥当。
A9: 237 | B9: 001Nn00000eVXtA | C9: 8010701016022 | D9: 東芝テック株式会社 | E9: 架電可（G列訂正あり） | F9: G列訂正：子会社のため採用値は連結ではなく単体）：2026年3月期の連結売上高5,692.65億円は日本経済新聞の決算記事でも裏が取れ、数値・決算期自体は正しい | G9: ○ 妥当（G列訂正：子会社のため採用値は連結ではなく単体）：2026年3月期の連結売上高5,692.65億円は日本経済新聞の決算記事でも裏が取れ、数値・決算期自体は正しい。ただし同社は東芝の連結子会社（約50%出資）であり、§3-3により子会社はグループ連結を使えず「単体」300億以上でのみ可。G列が『5,692.65億円（2026年3月期・連結）』と連結値のみを記載しているのは判定根拠として不適切で、決算短信の個別業績＝2,688.61億円（268,861百万円・2026年3月期・個別）を採用値とすべき。※本検証では個別268,861百万円を承認ソース上で再現できず（連結値のみが返る）、決算短信PDF巻末の個別業績で最終確認を推奨。単体でも300億を大幅超過するため架電可否は○のまま。
A10: 245 | B10: 001Nn00000eVY2N | C10: 9011001036346 | D10: テルウェル東日本株式会社 | E10: 架電可（G列訂正あり） | F10: G列訂正：採用値・決算期が承認ソースで再現できず）：G列『607億円（2025年度）』は自社ドメイン（telwel-east.co.jp）へのドメイン限定検索を2回（うち1回は金額607億をシード指定）行っても | G10: ○ 妥当（G列訂正：採用値・決算期が承認ソースで再現できず）：G列『607億円（2025年度）』は自社ドメイン（telwel-east.co.jp）へのドメイン限定検索を2回（うち1回は金額607億をシード指定）行っても一度も再現しなかった。再現できたのは①官報決算公告（catr.jp収録）の2024年3月期・単体売上高602億15百万円、②2025年3月期（決算末日2025/3/31）は決算公告が貸借対照表のみで売上高の記載なし（純利益6億円・利益剰余金33.65億円・総資産80.74億円のみ）、③『2025年3月時点614億円』はマイナビ・Wikipedia・就活会議・Compalyze等の禁止ソースにのみ掲載（§6-6）。よってG列の607億円という値と『2025年度』という期はいずれも根拠不明で、602.15億円（2024年3月期・単体）に訂正すべき。判定自体は、NTT東日本傘下の子会社だが単体で600億円規模＝300億を大幅超過のため○のまま。※602.15億円の出典はcatr.jp経由のため§7-1（承認可否未確定）に留意、正式出典は自社HP会社概要・会社案内PDFで取り直すこと。
A11: 294 | B11: 001Nn00000eVYcn | C11: 4290801020346 | D11: 株式会社ワールドインテック | E11: 架電可（G列訂正あり） | F11: G列訂正：金額に疑義）：ワールドHDの子会社だが単体で300億を大きく超えるため架電可否は○ | G11: ○ 妥当（G列訂正：金額に疑義）：ワールドHDの子会社だが単体で300億を大きく超えるため架電可否は○。ただしG列の988.57億円は再現できず、2025年12月期のワールドインテック売上高を1,212.32億円（従業員19,662名）とする情報がある。ワールドHD連結は約2,844億円（2026年12月期予想3,003.26億円＝前期比+5.6%から逆算）で、G列は連結値の誤用ではないことは確認。H列引用の有報URL（202603_Release-1.pdf）は本検証で実在確認できず、要再取得。
A12: 306 | B12: 001Nn00000eVYg5 | C12: 5020001074318 | D12: プレス工業株式会社 | E12: 架電可（G列訂正あり） | F12: G列訂正：決算期・金額の誤り確定）：架電可否は○のまま（どの期でも1,700億円超） | G12: ○ 妥当（G列訂正：決算期・金額の誤り確定）：架電可否は○のまま（どの期でも1,700億円超）。本検証で再確認したところ2026年3月期は会社計画で連結売上高1,730億円（前期比8.9%減）・営業利益88億円であり、G列の『2,021.67億円（2026年3月期・連結）』は2026年3月期の値ではない（2024年3月期実績とみるのが整合的、2025年3月期実績は約1,899億円）。判定不変だがG列は業績ハイライト／2026年3月期決算短信の確定実績に差し替え要。
A13: 311 | B13: 001Nn00000eVYgL | C13: 4120001086023 | D13: ナカバヤシ株式会社 | E13: 架電可（G列訂正あり） | F13: G列訂正：金額・決算期に疑義）：600億円台で300億は大幅超過のため架電可否は○ | G13: ○ 妥当（G列訂正：金額・決算期に疑義）：600億円台で300億は大幅超過のため架電可否は○。本検証でも2026年3月期の確定連結売上高は承認ソースから再現できず、確認できたのは2025年3月期実績627.67億円（前期比+2.8%）と2026年3月期会社予想635.00億円。G列の615.98億円はどちらとも一致せず前々期以前の値の可能性が高い。H列引用の決算短信PDF（日本語ファイル名）も実在確認できず、2026年3月期決算短信の確定値とURLで要差し替え。上場親会社（東証スタンダード7987）で親子判定は問題なし。
... A256: 4414 | B256: 001Nn000018keql | C256: 4011101030492 | D256: PayPay銀行株式会社 | E256: 架電可（G列訂正あり） | F256: G列訂正 | G256: ○ 妥当（G列訂正推奨）：921億円は承認ソースで再現できず、通期版決算参考資料も未確認。自社「2024年度決算参考資料」で2025年3月期・単体・経常収益719.12億円（前期比+114.77億/+18.9%、経常利益116.38億円）、「2026年3月期中間期決算参考資料」で中間期416.30億円を確認。G列は719.12億円（2025年3月期・単体・経常収益＝直近3期内）が安全。いずれも300億超で判定不変。

Sheet 要確認（薄いマージン）
A1: 行 | B1: 取引先名 | C1: 法人番号 | D1: 採用値_億円 | E1: 金額の出所 | F1: 余裕率 | G1: G列 | H1: I列
A2: 3491 | B2: 株式会社ムーンスター | C2: 7290001049191 | D2: 302.0 | E2: G列 | F2: 0.7 | G2: 302億円（2025年6月期・単体） | H2: ○ 妥当（余裕僅少・要再確認推奨）：moonstar.co.jpをドメイン限定で照会し、自社企業情報ページに「売上高302億円（2025年6月期）・従業員728名（2025年6月期）」の記載を確認しG列と一致。株式会社ムーンスター（法人番号7290001049191）は非上場の親会社で単体判定、§3-3問題なし。ただし300億基準に対する余裕が約2億と本ブロックで最も薄い。2026年6月期の値は承
A3: 3458 | B3: 株式会社シード | C3: 7010001003408 | D3: 303.36 | E3: G列 | F3: 1.1 | G3: 303.36億円（2026年3月期・単体） | H3: ○ 妥当：株式会社シード（東証スタンダード7743）は上場親会社のため連結値可（§3-3）。2026年3月期決算短信（2026年5月11日開示）で連結売上高339億4,200万円（前期比2.1%増）を確認し300億基準をクリア。G列の単体303.36億円も基準超えだが余裕が約3億と極めて薄いため、根拠は連結339.42億円に置くのが安全。単体303.36億と連結339.42億の差36億は子会社分と
A4: 1213 | B4: フォーデイズ株式会社 | C4: 6010001056010 | D4: 303.61 | E4: I列(訂正) | F4: 1.2 | G4: 303億円（2026年3月期・単体） | H4: ○ 妥当（G列訂正：303.61億円（2026年3月期・単体））：日本流通産業新聞オンラインで2026年3月期売上高303億6,100万円（前期比1.7％減）、経常利益26億8,900万円を確認。新聞社記事で決算期・売上高明記のため承認ソース（§3-4-4）。G列「303億円」は概数で誤りではないが正確には303.61億円。非上場・単体、親子問題なし、株式会社。ただし300億基準に対しマージンわず
A5: 4114 | B5: ＡＭＧホールディングス株式会社 | C5: 7180001049070 | D5: 304.18 | E5: G列 | F5: 1.4 | G5: 304.18億円（2025年3月期・連結） | H5: ○ 妥当（要注意・最新期未確認）：2025年3月期連結売上高30,417百万円＝304.17億円は決算短信（2025/5/14）とIRBANK転載（304億1765万円・前期比4.57%増）で二重確認、翌期予想「320億円（前期比5.2%増）」からの逆算とも整合。持株会社の連結値で§3-3適合。ただし①最新の2026年3月期決算短信（2026/5/14公表）の売上実績は5クエリ検索しても取得できず
A6: 1227 | B6: 株式会社ホンダカーズ静岡 | C6: 8080001009100 | D6: 304.38 | E6: I列(訂正) | F6: 1.5 | G6: 330.6229億円（2026年3月期・単体） | H6: ○ 妥当（G列訂正：304.3760億円（2025年3月期・単体））：自社HP会社概要で確認できるのは売上高304億3,760万円（2025年3月決算期）、従業員419名（2025年3月現在）。G列の「330.6229億円（2026年3月期）」は自社HP・新聞・公的機関いずれの承認ソースでも再現できず、2026年3月期の数値は未公表と判断。株主は「本田技研工業株式会社 他3名」＝本田技研の子会社に
A7: 1730 | B7: ネッツトヨタ茨城株式会社 | C7: 8050001002000 | D7: 307.0 | E7: G列 | F7: 2.3 | G7: 307億円（2025年3月期・単体） | H7: ○ 妥当（反証検証済み）：自社HP会社概要を独立に再検索し、売上高307億円（2025年3月決算）を資本金4,800万円・社員537名・設立1969年4月・新車26店舗＋中古車併売10店舗とセットで再現。当該法人単独の値でグループ合算ではない。なお同名紛れの「ネッツトヨタつくば」（ハタヤHDが全株取得）は別法人で取り違えなし。反証できず○維持。ただし基準300億に対し余裕2.3%しかなく、次期で微
A8: 717 | B8: 株式会社エーアイテイー | C8: 3120001075217 | D8: 307.98 | E8: G列 | F8: 2.7 | G8: 307.98億円（2026年2月期・単体・営業収益） | H8: ○ 妥当：東証プライム上場の親会社（国際フォワーダー）のため連結採用可。2026年2月期の連結営業収益583.99億円（前期比5.0%増、営業利益41.96億円）を確認。G列の単体307.98億円は300億ぎりぎりで単独では脆いが、親会社判定により連結583.99億円で条件充足が確定。原文表記は「営業収益」。
A9: 3239 | B9: 株式会社流通サービス | C9: 9030001035744 | D9: 308.0 | E9: G列 | F9: 2.7 | G9: 308億円（2026年3月期・単体） | H9: ○ 妥当：自社サイト企業概要で「売上高308億円（2026年3月期）」を確認し、自社ドメイン限定の再検索でも同値を再現（採用ページ「数字で見る流通サービス」も同様）。埼玉県草加市遊馬町の消費物流・生協物流企業で、法人番号9030001035744・所在地・従業員5,006名と整合し同名企業の取り違えなし。ただし基準300億に対する超過幅が8億円と極めて薄く、次期決算の下振れや期ズレで反転しうる要監
A10: 1686 | B10: 大成ユーレック株式会社 | C10: 3010701005574 | D10: 308.11 | E10: G列 | F10: 2.7 | G10: 308.11億円（2026年3月期・単体） | H10: ○ 妥当（G列訂正必須：308.11億円/2026年3月期を4回の独立検索で一度も再現できず）：一般検索・金額シード検索・u-lec.comドメイン限定検索・官報決算公告検索の4本すべてで「2026年3月期の売上高データは見つからない」と返り、返るのは一貫して376億78百万円（2025年3月期）のみ。G列の数値・決算期は1次の誤りの疑いが濃厚。ただし376.78億円の出所はマイナビ/Wikipe
A11: 1180 | B11: 株式会社ミルックス | C11: 8010001058475 | D11: 308.2 | E11: G列 | F11: 2.7 | G11: 308.20億円（2026年3月期・単体） | H11: ○ 妥当（本ブロック最薄・要再確認）：清水建設グループの子会社だが単体308.20億円（令和8年＝2026年3月期）で§3-3適合。308億2,000万円＝308.20億円で桁検算一致。■最大の弱点：基準300億に対し余裕わずか2.7%。承認ソース（自社HP会社概要）の記載として1次が採った値だが、2回の検索で2026年3月期308.20億を承認ソース側から再現できず、返ったのは2025年3月期3
A12: 1994 | B12: 群馬県卸酒販株式会社 | C12: 8070001000877 | D12: 308.55 | E12: G列 | F12: 2.9 | G12: 308億5,500万円（2025年度・単体） | H12: ○ 妥当（2次検証・数値は再現できず／結論は維持）：会社概要ページ https://www.g-shuhan.co.jp/overview/ は実在するが、追加3回の検索でも本文の308億5,500万円／グループ366億6,000万円を再現できなかった。ただし別検索で「2024年3月実績 売上高312億7,000万円」が出ており、年商310億前後という規模感は裏付けられる。300億を下回る数値はど
A13: 14 | B13: エフピコ商事株式会社 | C13: 1240001030013 | D13: 309.0 | E13: G列 | F13: 3.0 | G13: 309億円（2025年3月期・単体） | H13: ○ 妥当：自社ドメイン内の採用ページ「数字で見るエフピコ商事」（承認ソース系統⑨）に「売上高 309億円（2025年3月期）」と記載されているのを確認でき、G列と一致。同ページの従業員数が「2026年1月時点189名」と最新のため、2025年3月期が現時点の最新公表値と判断でき§3-8も満たす。エフピコの子会社だが単体309億円で300億以上のため§3-3をクリアしており、親の連結値2,221億円
... A209: 2 | B209: 常洋水産株式会社 | C209: 1050001001165 | D209: 398.64 | E209: G列 | F209: 32.9 | G209: 398.64億円（2026年3月期・単体） | H209: ○ 妥当（1次の△を覆す）：どちらの数値を採っても300億を大きく超え、架電可否の結論は動かない。追加でjoyosuisan.com「会社概要」「ごあいさつ」を3クエリ再検索したが、いずれも1次と同じ「2025年3月期 売上高388.39億円／経常利益6.08億円／従業員 男220名・女136名（2025年3月31日現在）」を返した。従業員数の基準日が2025年3月31日で固定されている＝検索イン

Sheet 先方確認事項
A1: 先方確認事項（TOKIUM 直アポ大 G/H列検証）
A3: 【確定済み】§7-1 catr.jp は承認ソースとして扱う
A5: 判断：認める。 御社にお伺いを立てずにこちらで確定させました。理由は2つです。
A7: 1. 同じRULESの §5-3 が官報決算公告を承認ソースの実績として挙げています。
A8: 「フォンテラジャパン・豊田スチールセンター → 官報決算公告から取得」と明記されており、
A9: ルール自身が官報決算公告を承認ソースとして扱っています。
A10: にもかかわらず、そのフォンテラジャパン（行4）が出典catr.jpゆえに架電不可になっていました。
A11: 2. §7-1 自身が代替経路の不在を認めています。
A12: 「官報のオンライン無料公開は直近90日分のみで、過去の決算公告は遡及できない。
A13: そのため catr.jp のような二次サイトを使わざるを得ないケースが出る」と書かれています。
A15: 適用結果
A17: catr.jp / §7-1 が絡む 672行を1行ずつ読んで仕分けし、114行を架電可に回収しました。
... A500: 従業員2,000名規模とも整合するため、本文が読めれば×（300億未満）に倒れる公算が高い。

Sheet 再検証で見直した行
A1: 行 | B1: 取引先名 | C1: 法人番号 | D1: 見直しの結果 | E1: きっかけ | F1: 最終判定 | G1: I列_検証結果 | H1: J列_ソース
A2: 415 | B2: 株式会社アペックス西日本 | C2: 5120001140828 | D2: 架電不可へ | E2: 未再現の架電可行を優先監査 | F2: 架電不可（△要再確認） | G2: △ 妥当（維持）。回収を試みたが不可。①法人同定：法人番号5120001140828は登記所コード1200（大阪法務局本局）で所在地と整合。本店＝大阪府大阪市平野区長吉川辺4丁目1番5号、設立2009年11月2日、資本金6,406万円、代表取締役 森吉平（親会社アペックスおよび行3401の法人と同一人物）。アペックスグループの子会社で相違なし。②今回新たに当たった経路＝親会社自社HPの会社概要／グループ紹介ページ、同社サスティナビリティレポート（env_2022・env_2020・env_2019）、gBizINFO（5120001140828。決算情報の掲載なし）、官報決算公告DB（親会社アペックスの第60〜62期は存在するが、アペックス西日本単体の公告は確認できず）。いずれにも当社単体の売上高の記載なし。③親会社の承認ソースからは上限しか言えない：親会社会社概要の372億円（2025年12月末時点）は「アペックス西日本を含む」合算値であり、当社単体が372億未満であることは確実だが、300億未満であることまでは承認ソースだけでは確定できないため×にはできない。④禁止ソースには142億円（2023年12月末・マイナビ）／185億円（Baseconnect等）が流通しており、いずれも300億を大幅に下回る。親会社側の社員数が900名（単体）に対し当社600名規模である点とも整合し、単体300億未満の公算は極めて高い。§3-3により子会社は単体300億以上のみ可のため、回収の見込みはなく、むしろ将来的に×へ倒れる候補。ただし承認ソースに単体値が無い以上、現時点の正しい結論は△（載せてはいけない）。 | H2: https://www.apex-co.co.jp/profile/profile.html ; https://www.apex-co.co.jp/profile/group.html ; https://info.gbiz.go.jp/hojin/ichiran?hojinBango=5120001140828 ; https://houjin.jp/c/5120001140828 ; （参考。承認ソースではない）https://job.mynavi.jp/26/pc/search/corp56099/outline.html
A3: 481 | B3: 株式会社日本アメニティライフ協会 | C3: 2020001007809 | D3: 架電不可へ | E3: 300〜350億の境界帯を再検証 | F3: 架電不可（△要再確認） | G3: △ 確認不可（降格）。採用値309.23億円を承認ソースで再現できず。自社HP会社情報(jala.co.jp/aboutus)で取得できるのは連結237億2,946万円（2022/4/1〜2023/3/31）のみで、①300億円未満、②2023年3月期＝直近3期外（§3-8）、の二重の問題がある。自社ドメインの決算公告PDF（2025年6月掲出）は貸借対照表のみ（資産合計21,304百万円）で損益計算書がなく売上高を確認できない。309億の記載は catr.jp／Baseconnect／FUMA／エン等の禁止ソースのみ（§3-4）。独立再検索でも承認ソース上に300億以上の根拠は見当たらず。§3-5により直アポ大に載せてはいけない。 | H3: https://jala.co.jp/aboutus/; https://jala.co.jp/wp-content/uploads/2025/06/2025-%E6%B1%BA%E7%AE%97%E5%85%AC%E5%91%8A%E3%83%87%E3%83%BC%E3%82%BF%EF%BC%88JALA%EF%BC%89.pdf
A4: 2703 | B4: 日本メディカルシステム株式会社 | C4: 7040001027214 | D4: 架電不可へ | E4: 300〜350億の境界帯を再検証 | F4: 架電不可（△要再確認） | G4: △ 確認不可（採用値347億円は承認ソースで再現不能）：jmsys.co.jp・EDINET・決算公告・官報を当たったが、347億円を決算期付きで示す承認ソースは存在しない。347億が載るのはSalesNow・Baseconnect・doda・マイナビ・OpenWork等の禁止ソースのみ（§6-6）。自社サイトで確認できるのは「売上高308億円（2025年4月現在／直営店売上）」で、何年何月期か不明のため§3-8を満たさず、店舗ベース表記のため§3-7の売上高とも断定できない。308億でも基準まで8億の薄マージン。非上場・資本金5,000万円で有報・決算短信なし。同名の日本メディカルシステムホールディングス（法人番号7011701017226）との取り違えリスクもあり。§3-5により直アポ大には載せない。 | H4: https://www.jmsys.co.jp/company/; https://www.jmsys.co.jp/
A5: 3112 | B5: 株式会社キョウデン | C5: 5010001248525 | D5: 架電不可へ | E5: 未再現の架電可行を優先監査 | F5: 架電不可（△要再確認） | G5: △ 確認不可を維持（回収失敗）。ただし前提が2点判明。①上場区分＝親エージェントの想定と異なり非上場。旧キョウデン(6881)は創業者・橋本浩氏によるTOB／株式売渡請求を経て2023年10月3日に東証が上場廃止を決定、2023年10月26日上場廃止（JPX開示で確認）。したがって決算短信・有報は2023年3月期提出分が最後で、§5-3の2〜4（有報・短信・TDnet）経路は直近3期には使えない。②法人格＝対象の法人番号5010001248525は2024年9月25日に新規指定された『株式会社ファウンテン』が2025年1月6日に『株式会社キョウデン』へ商号変更したもので、本店は長野県上伊那郡箕輪町大字三日町482番地1（旧キョウデンと同一）。2025年1月17日に旧キョウデン(6100001021517)を吸収合併して存続＝現存する事業会社であり、株式会社・オーナーは個人のため§3-3上は親会社側（連結可）。③数値＝66,725百万円＝667.25億円は2023年3月期の連結売上高（前期57,358百万円＝573.58億円に対し+16.3%、営業利益4,226百万円・6.3%、親会社株主帰属当期純利益2,900百万円で検算一致）。ただし出典はkabutan／Yahoo!ファイナンス／buffett-code／bm.sp-21等の非承認ソースで、かつ§3-8の直近3期（2024年3月期・2025年3月期・2026年3月期）から外れる4期前のため採用不可。承認ソースとしては自社HP掲載の2023年3月期有報PDF(ir_20230630-01.pdf)が同数値を含むはずだが本文未読、いずれにせよ鮮度で失格。④直近期＝自社HPの決算公告 2024年3月期(news20240604-01)・2025年3月期(news20250630-01) の存在は再確認したが、ドメイン限定検索を5パターン（決算公告＋売上高／第43期＋資産の部／業績ハイライト推移／会社概要＋連結売上高／数字で見るキョウデン）試しても本文の数値がスニペットに一切出ず到達不能。会社概要から得られたのは資本金1億円・従業員1,021名（2025年3月31日現在）・設立1983年7月のみ。⑤2026年3月期の決算公告は現時点で掲載を確認できず。規模感は667億円級で300億未満の懸念はないが、承認ソースで直近3期の実額に到達できないため△が正しい結論。残る経路は news20250630-01／news20240604-01 の本文（WebFetch必要）と官報本体の掲載号特定の2つのみ。 | H5: https://www.kyoden.co.jp/news/news20250630-01/; https://www.kyoden.co.jp/news/news20240604-01/; https://www.jpx.co.jp/news/1023/20231003-13.html; https://toukibo.ai-con.lawyer/search-service/result/5010001248525; https://www.kyoden.co.jp/corporate/profile/; https://www.kyoden.co.jp/content/wp-content/uploads/2023/06/ir_20230630-01.pdf
A6: 3401 | B6: 株式会社アペックス | C6: 5010001010216 | D6: 架電不可へ | E6: 未再現の架電可行を優先監査 | F6: 架電不可（△要再確認） | G6: △ 判定を覆す（架電可→架電不可）。372億円はこの法人の数値ではない。①法人番号の構造で決着：法人番号は1法人1番号であり、2〜5桁目＝設立登記の登記所コードは本行5010001010216＝0100（東京法務局本局）、3478の1180001092373＝1800（名古屋法務局本局）。チェックデジットも両者とも正当で、両者が同一法人（本店移転の前後）である可能性は構造上ない＝別法人が2社実在することが確定。前任者が3401に残した「本店移転か同名別法人か未解決」はこれで解消。②apex-co.co.jp（売上高372億円）の主体は3478側：gBizINFOの1180001092373が本店＝愛知県大府市柊山町2丁目418番地・設立1963年02月22日・従業員1,409人・業種「飲料自販機オペレーター」で自社HP会社概要（本社＝大府市柊山町2-418／設立昭和38年2月／資本金5,000万円）と完全一致し、官報決算公告（第60〜62期。1963年設立と期数が整合）もcatr.jp・PRTIMESとも法人番号1180001092373で採番されている。1984年前後設立の本行では第60期台に到達しない。③本行の法人の売上高は承認ソースに皆無：自社HP・EDINET・決算公告・gBizINFO・公的機関のいずれにも本行法人単独の売上高記載なし。加えて二次サイト間で設立年が1984年4月（アラームボックス）と1963年2月（全国法人リスト）に矛盾しており、同定そのものが固まらない。代表者は森吉平で3478・415と共通のためアペックスグループ内の法人と推測されるが、自社HPのグループ紹介ページが掲げるグループ会社（アペックス／アペックス西日本／名古屋フーヅ→アペックスPV／日本ベンダー整備）に東京の本法人は現れず、仮にグループ内でも§3-3の子会社扱いで単体300億以上の立証が必要。よって§3-5により載せてはいけない。なお本行と3478はリスト上の同名重複であり、実体は3478が本物。 | H6: https://www.apex-co.co.jp/profile/profile.html ; https://info.gbiz.go.jp/hojin/ichiran?hojinBango=1180001092373 ; https://prtimes.jp/finance/1180001092373/settlement ; https://houjin.jp/c/5010001010216 ; （同定の突合に参照。承認ソースではない）https://alarmbox.jp/companyinfo/entities/5010001010216
A7: 4225 | B7: 株式会社ダイヤモンドダイニング | C7: 4010401130622 | D7: 架電不可へ | E7: 未再現の架電可行を優先監査 | F7: 架電不可（△要再確認） | G7: △ 単体実額を承認ソースで確定できず。株式会社ダイヤモンドダイニング（法人番号4010401130622／東京都港区芝4-1-23 三田NNビル18F）は株式会社DDグループ(3073)の連結子会社（連結子会社10社ほか計14社）で、§3-3により単体300億以上が必須。親会社連結は385.78億円（38,578百万円・2025年2月期／DDグループ会社概要PDF・決算短信）、2026年2月期通期予想415.6億円。DD自社サイト会社概要は「売上高405億円・資本金4,000万円・社員1,293名/パートナー6,050名」と記載するが、親会社DDグループの会社概要（資本金40百万円＝4,000万円、連結従業員6,786名＝社員1,234名/パートナー5,552名、事業内容の文言も同一）と資本金・従業員区分・事業内容が完全一致しており、この405億円は連結値の転記の疑いが濃厚（他9社がある以上、連結405億とDD単体405億は両立しない）。有報「関係会社の状況・主要な損益情報等」で拾えたのは2018年2月期分のみでDD単体7,560,035千円＝75.60億円（持株会社移行直後の変則期）＝§3-8で採用不可。直近期の単体売上高は決算公告・官報DB(catr.jp)・EDINET/irbank・自社HPいずれからも実額未到達。前段I列の「328.71億円（32,871,473,250円）」は再現できず根拠PDF未確認のため採用しない。連結385.78億のうち飲食・アミューズメント94%（約362億）からエスエルディー・湘南レーベル等を控除すると単体は300億前後の境界域で、300億超も未満もあり得る。よって現状のまま直アポ大に載せるのは不可、単体実額（有報「関係会社の状況」原文または決算公告）の再確認が必要。 | H7: https://www.dd-grp.com/wpsys/wp-content/themes/dd_group_v1/assets/images/about/companyprofile_260202.pdf;https://www.diamond-dining.com/company/info/outline/;https://f.irbank.net/pdf/20250414/140120250414514699.pdf;https://f.irbank.net/pdf/E05673/ir/S100D1PU.pdf;https://irbank.net/E05673/edinet;https://www.dd-grp.com/ir/library2/
A8: 4347 | B8: パーソルマーケティング株式会社 | C8: 8011101017783 | D8: 架電不可へ | E8: 未再現の架電可行を優先監査 | F8: 架電不可（△要再確認） | G8: △ 確認不可を維持（回収失敗）。今回の追加調査＝①persol-mk.co.jp ドメイン限定検索を4パターン（「決算報告書」単独／「決算公告 電子公告」／「労働者派遣事業 情報公開 マージン率」／「会社概要 資本金 売上高」）実施したが、決算報告書PDFの一覧ページも新しい期のPDFも一切ヒットせず。②ファイル名パターン set2203/set2403/set2503_marketing.pdf を直接検索語にしたが該当なし（到達可能なのは2021年3月期 set2103 のみで§3-8の直近3期外、これは前回と同じ）。③法人格＝2021年10月1日にパーソナル株式会社を吸収合併した存続会社であることを自社ニュースリリースで確認、消滅していない（株式会社・存続）。④§3-3上は「子会社（パーソルHD傘下）」なので単体300億以上が必須。パーソルHD第18期有報（2025年4月〜2026年3月）を含めHD側IRを再確認したが、10%基準未満のため関係会社の状況に単体売上高の記載なしという前回結論は覆らず。⑤参考情報として非承認ソース（SalesNow／Baseconnect／doda等）に「2023年3月期 売上高199億5,249万円＝199.52億円」「従業員2,026〜2,655名」の記載を確認。承認ソースではないためG列には採用できないが、規模感（人材・販売支援業で従業員2千名規模）とも整合し、単体300億超の可能性は低い。よって回収見込みは薄く△維持が妥当。残る唯一の未踏経路は「自社HP掲載の最新期決算報告書PDFの直URL特定」で、WebSearchのスニペット経由では到達不能。WebFetchが使える環境なら www.persol-mk.co.jp のサイト内を辿れば回収可能性がある。 | H8: https://persol-mk.co.jp/company/newsrelease/16624 ; https://sales.persol-mk.co.jp/company ; https://www.persol-mk.co.jp/sales/wp-content/themes/persol-mk-2021/assets/documents/set2103_marketing.pdf ; https://www.persol-group.co.jp/ir/upload_file/m009-/20260622_FY2025Q4_SecuritiesReport.pdf ; https://info.gbiz.go.jp/hojin/ichiran?hojinBango=8011101017783
A9: 4391 | B9: 株式会社久原本家グループ本社 | C9: 5290001063310 | D9: 架電不可へ | E9: 300〜350億の境界帯を再検証 | F9: 架電不可（△要再確認） | G9: △ 確認不可（降格）。採用値336億円（2026年2月期）は独立検証で一度も再現せず、承認ソースに存在しない。自社公式サイトで確認できるのはグループ売上高303億〈2023年2月期〉→318億〈2024年2月期〉→327億〈2025年2月期〉の系列のみ。最新327億でも超過は9%と薄い。決定的な問題として、この「グループ売上高」が法定連結か9社の単純合算かを承認ソースで特定できず。製造（久原本家食品）と販売（久原本家・久原醤油）が別法人で内部取引が大きく、単純合算なら内部消去後に300億割れが現実的。本社自体は経営管理会社で単体は300億に遠く及ばない。§3-5により直アポ大から除外。当たったソース：自社サイト会社概要／グループ紹介、gBizINFO（5290001063310）、官報決算公告検索（数値に到達せず）。 | H9: https://kubarahonke.com/company/aboutus/; https://kubarahonke.com/company/; https://kubarahonke.com/company/business/; https://info.gbiz.go.jp/hojin/ichiran?hojinBango=5290001063310
A10: 4 | B10: フォンテラジャパン株式会社 | C10: 2010401046060 | D10: 架電可へ | E10: §7-1確定により回収 | F10: 架電可（回収） | G10: ○ 回収（§7-1確定）：フォンテラジャパン株式会社 単体859.71億円（第45期・2025年7月期）。金額は独立の検索結果でも第45期売上高約859.7億円と一致し整合。§6-6で警告されている流通値「800億2,500万円」（Yahoo!しごとカタログ／SalesNow／Baseconnect）には引きずられていない。法人格は株式会社で問題なく（§3-6充足）、外資日本法人だが単体で300億を大きく超える（§3-3充足）。決算期も直近3期以内で§3-8充足。出典は官報決算公告（catr.jp 収録）。§7-1 は承認する方針で確定。 | H10: https://catr.jp/companies/620b2/148115/settlements/cc9b1/435657; https://ryo-nakamura1.hatenablog.jp/entry/2026/01/30/170000_4
A11: 22 | B11: 株式会社翔薬 | C11: 7290001012769 | D11: 架電可へ | E11: §7-1確定により回収 | F11: 架電可（回収） | G11: ○ 回収（§7-1確定）：株式会社翔薬 単体1,970.68億円（2026年3月期）。金額は独立検索でも売上高1,970億6,800万円（前年比6.56%増）と一致し整合。スズケンの完全子会社だが単体で300億を大きく超えるため§3-3充足。自社HP会社概要・スズケンIRには売上高の記載がなく、承認ソースは官報決算公告のみ。決算期は直近期で§3-8充足。出典は官報決算公告（catr.jp 収録）。§7-1 は承認する方針で確定。 | H11: https://catr.jp/companies/546e2/14488; https://www.shoyaku.com/company/companyinfo/index.html
A12: 63 | B12: オムロンヘルスケア株式会社 | C12: 7130001024920 | D12: 架電可へ | E12: §7-1確定により回収 | F12: 架電可（回収） | G12: ○ 回収（§7-1確定）：オムロンヘルスケア株式会社 単体845.19億円（2025年3月期）。オムロンの子会社を単体基準で判定しており§3-3充足、300億を大きく超える。代替経路（自社サイト社史データの「2022年度 売上高1,421億円」は4期前で§3-8の鮮度切れかつヘルスケア事業ベースの疑い、親会社オムロンのIRはヘルスケア事業セグメント値のみで会社単体の開示なし）は使えず、承認ソースは官報決算公告のみ。決算期は直近3期以内で§3-8充足。出典は官報決算公告（catr.jp 収録）。§7-1 は承認する方針で確定。 | H12: https://catr.jp/companies/0f812/11019/settlements/2f389/410086; https://www.healthcare.omron.co.jp/corp/companyhistory/data.html; https://www.healthcare.omron.co.jp/corp/outline.html
A13: 66 | B13: ニプロファーマ株式会社 | C13: 3120001087781 | D13: 架電可へ | E13: §7-1確定により回収 | F13: 架電可（回収） | G13: ○ 回収（§7-1確定）：ニプロファーマ株式会社 単体1,054.01億円（2026年3月期）。金額は複数ソースで整合。ニプロの子会社だが単体で300億を大きく超え§3-3充足。ニプロ有価証券報告書は同社を特定子会社（売上高が連結売上高の10%超）と記載しており、桁の水準もこれと整合する。ニプロ有報・自社HP会社概要に単体数値の開示はなく、承認ソースは官報決算公告のみ。決算期は直近期で§3-8充足。出典は官報決算公告（catr.jp 収録）。§7-1 は承認する方針で確定。 | H13: https://catr.jp/companies/b0d12/14522/settlements/e08ab/463946;https://www.nipro.co.jp/assets/document/ir_library/72nd/securities_report.pdf;https://www.nipro.co.jp/ir/library/
... A118: 3419 | B118: 株式会社メガスポーツ | C118: 9010001084082 | D118: 架電可へ | E118: §7-1確定により回収 | F118: 架電可（回収） | G118: ○ 回収（§7-1確定）：475.45億円（2026年2月期・単体）。官報決算公告で確認済み。§6-2法人番号照合＝9010001084082は登記所0100・東京法務局本局で同名別法人ではない。検算＝親会社イオンは連結営業収益約10兆円規模でその10%＝約1兆円のため475億円は有報「関係会社の状況」に実額が記載されず、親会社ルートは原理的に不成立。子会社だが単体で300億基準を超過（§3-3）。出典は官報決算公告（catr.jp 収録）。§7-1 は承認する方針で確定。 | H118: https://www.megasports.jp/corporation/outline/; https://info.gbiz.go.jp/hojin/ichiran?hojinBango=9010001084082
A119: 3431 | B119: 株式会社アライドマテリアル | C119: 6010401059967 | D119: 架電可へ | E119: §7-1確定により回収 | F119: 架電可（回収） | G119: ○ 回収（§7-1確定）：468.3億円（2026年3月期・単体）。官報決算公告で確認済み。検算＝親会社は住友電気工業で連結約4.4兆円、その10%＝約4,400億円のため468億円は有報「関係会社の状況」の実額掲載対象外であり、親会社有報経路では取得できない（下限証明も不成立）。§6-2照合＝法人番号6010401059967の登記所コード0104＝東京法務局港出張所で本社（港区）と一致、同名別法人なし。社名・種別とも株式会社で§3-6充足。子会社だが単体で300億超のため§3-3クリア。出典は官報決算公告（catr.jp 収録）。§7-1 は承認する方針で確定。
A120: 3475 | B120: 株式会社ソーシン | C120: 3030001027053 | D120: 架電可へ | E120: 300〜350億の境界帯を再検証 | F120: 架電可 | G120: ○ 妥当：自社HP会社概要／業績ページの2025年度売上高331億円を再検索で再現。加えて官報決算公告ベースの第124期（2025年3月期）単体売上高約339億円とも整合し、日野自動車100%子会社ながら単体で300億超を確認（§3-3充足）。従業員663名（2026年3月末）、本社=埼玉県入間市、法人番号3030001027053で照合済み。自社HP値が単体かグループ計かの明示はないが、決算公告の単体値が同水準のため判定は動かない。超過は約31億と薄く要ウォッチ。 | H120: http://www.sohshin-net.co.jp/company;http://www.sohshin-net.co.jp/IR
A121: 3478 | B121: 株式会社アペックス | C121: 1180001092373 | D121: 架電可へ | E121: 未再現の架電可行を優先監査 | F121: 架電可（G列訂正あり） | G121: ○ 妥当（G列訂正：372億円は単体でなくアペックス＋アペックス西日本の合算値。G列に「グループ合算値」と明記すべき）。①法人同定は確定：法人番号1180001092373は登記所コード1800（名古屋法務局本局）で、gBizINFOの本店＝愛知県大府市柊山町2丁目418番地・設立1963年02月22日・従業員1,409人・「飲料自販機オペレーター」が自社HP会社概要（設立昭和38年2月・資本金5,000万円）と一致。官報決算公告第60〜62期も同法人番号に紐づく。存続法人であることも確認（2023年1月1日に株式会社アペックスPV〈旧・名古屋フーヅ〉を吸収合併して同社が解散、最新登記更新2025年1月6日）。「吸収合併されました」の表記は他社を吸収した側の意味で、本法人の消滅ではない。②数値と鮮度：自社HP会社概要に売上高372億円（2025年12月末時点）。直近期であり§3-8を満たす。③重要な訂正＝372億円は単体ではない：同ページに「社員数・売上高はアペックス西日本を含む」旨の注記があることを検索スニペット経由で2経路から独立に再確認。社員数も900名（単体）／1,400名（グループ計）と書き分けられており、売上高がグループ計であることと整合。サスティナビリティレポート系の旧版会社概要も「390億円（令和3年度実績）／社員数1,500名／営業拠点87ヵ所（令和3年12月末）はアペックス西日本を含む」、2020年版も「530億円（令和元年度実績）…西日本を含む」と一貫して合算表記。④単体は300億未満の公算：西日本の売上高は142億円（2023年12月末）〜185億円が流通しており（マイナビ／Baseconnectで§3-4の禁止ソース。参考値のみ）、差し引くとアペックス単体は約190〜230億円と推定され300億を割る。⑤それでも可となる根拠：本行はアペックスグループの中核親会社（グループ紹介ページを自社運営し、アペックス西日本・日本ベンダー整備・アペックスPVを擁し、アペックスPVを吸収合併済み）。§3-3の「親会社／HDは単体300億未満でもグループ連結300億超ならOK」に該当するため架電可。残る疑問＝372億円は連結ではなくアペックス＋西日本の単純合算であり、親会社であるという前提が崩れると成立しない。 | H121: https://www.apex-co.co.jp/profile/profile.html ; https://www.apex-co.co.jp/profile/group.html ; https://www.apex-co.co.jp/resources/files/env_2022.pdf ; https://info.gbiz.go.jp/hojin/ichiran?hojinBango=1180001092373 ; https://prtimes.jp/finance/1180001092373/settlement
A122: 3482 | B122: ヤンマーアグリ株式会社 | C122: 5160001007379 | D122: 架電可へ | E122: §7-1確定により回収 | F122: 架電可（回収） | G122: ○ 回収（§7-1確定）：1,355.47億円（2026年3月期・単体。前期比+11.57%・当期純利益47.70億円）。官報決算公告で確認済みで、第23期1,214.9億円（2025年3月期）・第22期979.77億円（979億7,700万円）と連続し整合。ヤンマーホールディングスの子会社だが単体で300億円を4.5倍超過し§3-3クリア。ヤンマー公式の決算情報ページ・gBizINFOでは単体値を取得できず。出典は官報決算公告（catr.jp 収録）。§7-1 は承認する方針で確定。 | H122: https://catr.jp/companies/5f71e/11303; https://www.yanmar.com/jp/about/company/ynm/; https://www.yanmar.com/us/about/finance/financial_results.html; https://info.gbiz.go.jp/hojin/ichiran?hojinBango=5160001007379
A123: 3491 | B123: 株式会社ムーンスター | C123: 7290001049191 | D123: 架電可へ | E123: 300〜350億の境界帯を再検証 | F123: 架電可 | G123: ○ 妥当（採用値を302億円に訂正・基準ギリギリ）：G列の320億円は誤り。自社HP moonstar.co.jp をドメイン限定で照会し、企業情報／会社概要に「売上高302億円（2025年6月期）・従業員728名（2025年6月現在）・資本金1億円」の記載を独立再現した。320億円は2020年6月期の業界記事（shoespost.jp／ふくおか経済）に出る「売上高320億円・11.5%減」由来の古い値で流用不可（前年度値をもっともらしく返す失敗様式）。正しい採用値は302億円（2025年6月期・単体）。株式会社ムーンスター（法人番号7290001049191）は非上場、単体で判定し§3-3問題なし。ただし300億基準に対する余裕は2億円＝0.7%と極めて薄く、2026年6月期（2026年6月末締め）の値は未公表。わずかな減収でも基準割れとなるため、架電前に自社サイト会社概要の更新確認を必須とすること。 | H123: https://www.moonstar.co.jp/corporate/profile/;https://www.moonstar.co.jp/corporate/info/summary.html
A124: 3516 | B124: サムスン電子ジャパン株式会社 | C124: 7010001119880 | D124: 架電可へ | E124: §7-1確定により回収 | F124: 架電可（回収） | G124: ○ 回収（§7-1確定）：1,960.9億円（第16期＝2023年12月期・単体）。官報決算公告で確認済みで、第15期2,157.98億円・第14期2,032.59億円と連続し整合。最新は第18期（2025年12月期／2026年4月6日公告）であり、第16期は直近3期の範囲内＝§3-8充足。金額は300億基準を6.5倍超過。自社HP・gBizINFOには売上高記載なし。gamebiz等の業界メディアは新聞社ではないため§3-4④に該当せず不採用。出典は官報決算公告（catr.jp 収録）。§7-1 は承認する方針で確定。 | H124: https://catr.jp/companies/f64ef/1080/settlements/353db/449712; https://kanpo-kanpo.blog.jp/archives/42174336.html; https://info.gbiz.go.jp/hojin/ichiran?hojinBango=7010001119880
A125: 3543 | B125: 光洋マテリカ株式会社 | C125: 3180001008253 | D125: 架電可へ | E125: §7-1確定により回収 | F125: 架電可（回収） | G125: ○ 回収（§7-1確定）：1,002.94億円（2026年2月期＝2026年2月28日決算・単体。100,294百万円＝桁検算済、前期比+13.28%、当期純利益21.53億円）。官報決算公告で確認済み（索引はcatr.jp・prtimes.com/finance）。300億基準を3.3倍超過。補強＝日本経済新聞2023/1/31記事に「2021年12月期の売上高は701億円」の明記あり（§3-4④の承認ソースだが§3-8の直近3期外のため参考）。検算＝親会社 岡谷鋼機（7485・議決権51.50%）の連結売上高約1兆円に対し単体1,002.94億円は約10%と開示境界上で、有報「関係会社の状況／主要な損益情報等」への実額掲載は未確認。子会社だが単体で300億超のため§3-3クリア。出典は官報決算公告（catr.jp 収録）。§7-1 は承認する方針で確定。 | H125: https://catr.jp/companies/1ade0/2556;https://prtimes.com/finance/3180001008253/settlement;https://www.nikkei.com/article/DGXZQOFD318EO0R30C23A1000000/;https://www.okaya.co.jp/storage/reports/Yi6Y9yNdAKGCgfNtQSZl8awpbnUNDADNthsYVFar.pdf;https://www.koyom.co.jp/
A126: 3999 | B126: 株式会社ＲＥＶＯＬＵＴＩＯＮ | C126: 8250001006187 | D126: 架電可へ | E126: 300〜350億の境界帯を再検証 | F126: 架電可 | G126: ○ 妥当（ただし高リスク・要再判定）：2025年10月期決算短信で連結売上高34,570百万円＝345.70億円を独立再現。桁検算一致。前期比621.1%増が正（前回の「521.1%への訂正」は誤りのため差し戻す）。検証中に別クエリが「31,239百万円」を返したが決算短信の34,570百万円が正。筆頭株主は合同会社ＦＯ１36.07%＝「その他の関係会社」であり親会社ではないため子会社に該当せず、§3-3により連結値でOK。ただし当期純損失172.32億円、2026年10月期中間の売上高は12,542百万円（125.42億円）と急減しており通期は300億割れが濃厚。不動産の一括取引による一時的膨張（§6-5）の疑いが強く、次回リスト更新時は降格の可能性大。 | H126: https://finance-frontend-pc-dist.west.edge.storage-yahoo.jp/disclosure/20251215/20251215520017.pdf;https://finance.biggo.jp/news/jpx_tdnet_140120260130542973
A127: 4114 | B127: ＡＭＧホールディングス株式会社 | C127: 7180001049070 | D127: 架電可へ | E127: 300〜350億の境界帯を再検証 | F127: 架電可 | G127: ○ 妥当（採用値を予想値から実績値へ訂正）：G列の320億円は2026年3月期の会社予想（32,000百万円・前期比5.2%増）であって実績ではない。独立検証の結果、2026年3月期通期連結の売上高実績は31,352百万円＝313.52億円（決算短信2026年5月14日公表）で、300億円を13.52億円上回る。前期2025年3月期は30,417百万円＝304.17億円（短信2025年5月14日）で、+3.1%の算術とも整合。桁検算31,352百万円＝313.52億円で正。持株会社の連結値のため§3-3適合、最新期のため§3-8適合。正しい採用値は313.52億円（2026年3月期・連結）。ただし超過幅は4.5%と薄く、中間期は▲2.8%の減収推移だったこと、2027年3月期は建築資材価格高騰・供給不安を理由に連結業績予想が「合理的に見通すことが困難」として未公表であることから、翌期に基準割れとなるリスクが高い要監視行。 | H127: https://www.amg-hd.co.jp/pdf/ir/tanshin/20260514tanshin.pdf;https://finance.stockweather.co.jp/contents/dispPDF.aspx?disclosure=20250514550904;https://irbank.net/8891
A128: 4234 | B128: リスパック株式会社 | C128: 2200001005819 | D128: 架電可へ | E128: §7-1確定により回収 | F128: 架電可（回収） | G128: ○ 回収（§7-1確定）：売上高570.02億円（第49期・決算末日2024年3月20日・単体／原文570億200万円、前年比+3.63%）を官報決算公告（2024年6月28日掲載）で確認。同公告の総資産565.08億円・純利益27.23億円と整合し、リスのプラスチックグループ連結1,137億円の約50%で規模も整合。子会社だが単体で300億を大きく超え§3-3充足。決算期は§3-8の直近3期以内。出典は官報決算公告（catr.jp 収録）。§7-1 は承認する方針で確定。 | H128: https://catr.jp/companies/888e9/11645/settlements/ed6af/363561; https://www.risu.co.jp/group/sales/; https://www.risu.co.jp/group/company/risupack/about/; https://info.gbiz.go.jp/hojin/ichiran?hojinBango=2200001005819
A129: 4304 | B129: 冨士機材株式会社 | C129: 9010001055397 | D129: 架電可へ | E129: §7-1確定により回収 | F129: 架電可（回収） | G129: ○ 回収（§7-1確定）：売上高1,685.10億円（2024年度・4月期決算・単体／168,510百万円。経常利益3,511百万円＝35.11億円、総資産95,466百万円＝954.66億円）。別途 第83期決算公告では売上高1,424.9億円・当期純利益11.74億円。いずれも300億を大幅超過。§6-1に従い百万円→億円を自前換算（検索要約の『1,424.9 billion yen』は桁誤りで原文は百万円単位）。§6-2照合＝法人番号2〜5桁0100＝東京法務局本局で本社・千代田区一番町と整合、1945年創業の建築設備資材専門商社で規模も整合。出典は官報決算公告（catr.jp 収録）。§7-1 は承認する方針で確定。 | H129: https://www.fujikizai-g.co.jp/company/overview/; http://www.fujikizai-g.co.jp/recruit/company/index.html; https://catr.jp/companies/efe74/83638/settlements/05c31/178222; https://kanpo.tremolo.work/company/58490
A130: 4316 | B130: コナミスポーツ株式会社 | C130: 9010701013613 | D130: 架電可へ | E130: §7-1確定により回収 | F130: 架電可（回収） | G130: ○ 回収（§7-1確定）：売上高494.97億円（第55期・単体。売上総利益42.78億円／営業利益20.60億円／経常利益19.35億円／当期純利益17.76億円）を官報決算公告で確認。コナミグループ連結4,216億円（2025年3月期）×10%＝421.6億円＜494.97億円で10%超に該当し規模も整合。子会社だが単体で300億を超え§3-3充足。出典は官報決算公告（catr.jp 収録）。§7-1 は承認する方針で確定。 | H130: https://catr.jp/companies/ebad0/8526 ; https://catr.jp/settlements/cb069/253179 ; https://kanpo-kanpo.blog.jp/archives/46199342.html ; https://www.konami.com/ir/ja/ir-data/
A131: 4333 | B131: 株式会社サッポロドラッグストアー | C131: 9430001020202 | D131: 架電可へ | E131: §7-1確定により回収 | F131: 架電可（回収） | G131: ○ 回収（§7-1確定）：売上高826.63億円（第39期・単体。前期＝第38期884.05億円）を官報決算公告で確認。法人番号9430001020202→登記所コード4300＝札幌法務局で札幌市本社と一致し同名別法人ではない。サツドラHD連結（約1,000億円規模）の8割超＝10%超で規模も整合。子会社だが単体で300億を大きく超え§3-3充足。法人格は現存（子会社シーラクンスを吸収合併した存続会社側）。出典は官報決算公告（catr.jp 収録）。§7-1 は承認する方針で確定。 | H131: https://catr.jp/companies/b4155/29774 ; https://prtimes.jp/finance/9430001020202/settlement/224749 ; https://satudora-hd.co.jp/ir/library/securities.php ; https://satudora-hd.co.jp/ir/library/securities2.php ; https://info.gbiz.go.jp/hojin/ichiran?hojinBango=9430001020202
... A137: 4373 | B137: 株式会社トーホーフードサービス | C137: 2140001029808 | D137: 架電可へ | E137: §7-1確定により回収 | F137: 架電可（回収） | G137: ○ 回収（§7-1確定）：売上高1,239.17億円（第16期・単体／原文1,239億1,700万円）を官報決算公告で確認。トーホー(8142)の連結子会社だが単体で300億を大きく超え§3-3充足。親会社トーホー有報『関係会社の状況』に当社の売上高が連結売上高の10%超である旨の注記あり（連結2,597.47億円／2026年1月期）で規模も整合。なお第18期公告は純利益32億8,400万円・総資産311億2,700万円のみで売上高欄がなく、総資産311.27億円は売上高ではないので不採用。法人番号2140001029808＝神戸地方法務局で本社・神戸市東灘区と一致。出典は官報決算公告（catr.jp 収録）。§7-1 は承認する方針で確定。 | H137: https://www.to-ho.co.jp/ir/securities.html; https://www.to-ho.co.jp/ir/highlight.html; https://catr.jp/companies/ee37e/2636; https://prtimes.jp/finance/2140001029808/settlement/450892
